Workbook
Name StatusProject: '_DANH_SÁCH'!$A$1:$A$5
Name YesNo: '_DANH_SÁCH'!$B$1:$B$2
Name Priority: '_DANH_SÁCH'!$C$1:$C$4
Name Decision: '_DANH_SÁCH'!$D$1:$D$7
Name Cadence: '_DANH_SÁCH'!$E$1:$E$6
Name CardStatus: '_DANH_SÁCH'!$F$1:$F$5
Name SourceType: '_DANH_SÁCH'!$G$1:$G$11
Name ScopeStatus: '_DANH_SÁCH'!$H$1:$H$3
Name Verification: '_DANH_SÁCH'!$I$1:$I$3
Name InboxStatus: '_DANH_SÁCH'!$J$1:$J$5
Name RiskOfBias: '_DANH_SÁCH'!$K$1:$K$5
Name PilotPhase: '_DANH_SÁCH'!$L$1:$L$11

Sheet BẮT_ĐẦU
A1: BẮT ĐẦU — CHƯƠNG TRÌNH CẬP NHẬT CHỨNG CỨ ĐA CHUYÊN NGÀNH
A2: Điền 4 vai trò → chọn đúng 2 dự án → mỗi tuần đi theo INBOX → PHIẾU → NGƯỜI DUYỆT → NHẬT KÝ QĐ
A3: DRAFT — CHƯA DUYỆT
B4: 1. THIẾT LẬP MỘT LẦN — chỉ chọn chuyên ngành sau khi đủ vai trò
B5: Vai trò bắt buộc | C5: Người/đầu mối | D5: Trạng thái | E5: Ghi chú
B6: Chủ Chương trình | C6: Người dùng — tự phụ trách | D6: ĐÃ XÁC NHẬN | E6: Mặc định dùng cho mọi dự án; không cần thiết lập lại
B7: Người/cấp phê duyệt thay đổi thực hành | C7: Người dùng — tự phụ trách | D7: ĐÃ XÁC NHẬN | E7: Người quyết định thực hành lâm sàng mặc định; mọi quyết định phải ghi NHẬT_KÝ_QĐ
B8: Phương pháp viên/evidence analyst | C8: Người dùng — tự phụ trách | D8: ĐÃ XÁC NHẬN | E8: Phương pháp viên mặc định cho mọi dự án; không thay thế bác sĩ chuyên ngành
B9: Đầu mối nhận chuyển cấp P0/P1 | C9: Người dùng — tự phụ trách | D9: ĐÃ XÁC NHẬN | E9: Đầu mối P0/P1 mặc định; tiếp nhận, chuyển đúng thẩm quyền và theo dõi đến khi đóng
B10: Lịch họp Evidence Inbox hàng tuần | C10: Thứ Hai 07:30 (Asia/Ho_Chi_Minh) | D10: ĐÃ LÊN LỊCH | E10: Automation: c-p-nh-t-ebm-tim-m-ch-v-n-i-ti-t · 15 chuyên ngành · rà an toàn toàn cục + chuyên sâu tuần tự
B11: Ngày bắt đầu dự kiến | D11: Không nhập dữ liệu người bệnh
B13: 2. BA VIỆC TIẾP THEO — workbook tự nhắc theo tiến độ
B14: =IF(COUNTIF(D6:D9,"ĐÃ XÁC NHẬN")<4,"1. Điền và xác nhận đủ 4 vai trò ở trên",IF(COUNTIF('DANH_MỤC_DỰ_ÁN'!O5:O200,"Có")<>2,"1. Chấm điểm và chọn đúng 2 dự án trong DANH_MỤC_DỰ_ÁN","1. Kiểm tra P0/P1 đang mở trong INBOX"))
B15: =IF(COUNTIF(D6:D9,"ĐÃ XÁC NHẬN")<4,"2. Chưa chọn chuyên ngành",IF(COUNTIF('DANH_MỤC_DỰ_ÁN'!O5:O200,"Có")<>2,"2. Giữ các dự án ở trạng thái Chưa bắt đầu cho đến khi được chọn","2. Mỗi dự án tạo 5–8 câu hỏi trong CÂU_HỎI"))
B16: =IF(COUNTIF(D6:D9,"ĐÃ XÁC NHẬN")<4,"3. Hoàn thành Tuần 1 trong CHECKLIST_90_NGÀY",IF(COUNTIF('DANH_MỤC_DỰ_ÁN'!O5:O200,"Có")<>2,"3. Ghi quyết định chọn dự án vào CHECKLIST_90_NGÀY","3. Cập nhật INBOX và NHẬT_KÝ_QĐ hằng tuần"))
B18: 3. LIÊN KẾT NHANH — bấm để đến đúng nơi cập nhật
B19: Đọc hướng dẫn workbook | D19: Chấm và chọn đúng 2 dự án | F19: Quản lý danh mục câu hỏi
B20: Đăng ký nguồn theo dõi | D20: Xử lý Evidence Inbox | F20: Theo dõi Evidence Update Card
B21: Ghi nhật ký quyết định | D21: Cập nhật checklist 90 ngày | F21: Xem dashboard tổng hợp
B24: 4. RÀO CỨNG — không được bỏ qua
B25: DRAFT — CHƯA DUYỆT
B26: KHÔNG TỰ ĐỔI THỰC HÀNH/PATHWAY/PHÁC ĐỒ; KHÔNG TỰ GÁN GRADE
B27: KHÔNG LƯU PII/THÔNG TIN ĐỊNH DANH NGƯỜI BỆNH
B28: P0/P1 PHẢI CHUYỂN BÁC SĨ/NGƯỜI CÓ THẨM QUYỀN

Sheet _DANH_SÁCH
A1: Chưa bắt đầu | B1: Có | C1: P0 | D1: NO CHANGE | E1: Liên tục | F1: DRAFT — CHƯA DUYỆT | G1: Guideline | H1: Trong phạm vi | I1: Đã xác minh | J1: Mở | K1: Thấp | L1: Tuần 1
A2: Đang thiết lập | B2: Không | C2: P1 | D2: WATCH | E2: Hàng tháng | F2: Đang duyệt | G2: Systematic review | H2: Ngoài phạm vi | I2: Chưa xác minh | J2: Đang xử lý | K2: Một số lo ngại | L2: Tuần 2
A3: Đang hoạt động | C3: P2 | D3: CLARIFY | E3: Hàng quý | F3: ĐÃ DUYỆT | G3: Meta-analysis | H3: Chờ làm rõ | I3: Không áp dụng | J3: Chờ duyệt | K3: Cao | L3: Tuần 3
A4: Tạm dừng | C4: P3 | D4: UPDATE SUMMARY | E4: 6 tháng | F4: Đã phát hành | G4: RCT | J4: Hoàn tất | K4: Chưa đánh giá | L4: Tuần 4
A5: Đã đóng | D5: PROPOSE PRACTICE UPDATE | E5: Hàng năm | F5: Đã đóng | G5: Cohort | J5: Loại có lý do | K5: Không áp dụng | L5: Tuần 5
D6: SAFETY ESCALATION | E6: Theo sự kiện | G6: Chẩn đoán | L6: Tuần 6
D7: RETIRE/SUPERSEDE | G7: Tiên lượng | L7: Tuần 7–8
G8: An toàn thuốc | L8: Tuần 9
G9: Cảnh báo quản lý | L9: Tuần 10
G10: Preprint | L10: Tuần 11
G11: Khác | L11: Tuần 12–13

Sheet DASHBOARD
A1: DASHBOARD CHƯƠNG TRÌNH
A2: Các chỉ số cập nhật khi nhập dữ liệu vào các sheet vận hành. Ô trống không được tính là hoàn thành.
A4: CHỈ SỐ | B4: GIÁ TRỊ | C4: MỤC TIÊU THÍ ĐIỂM | E4: Quyết định | F4: Số lượng
A5: Tổng số dự án | B5: =COUNTA('DANH_MỤC_DỰ_ÁN'!A5:A200) | C5: Theo danh mục | E5: NO CHANGE | F5: =COUNTIF('PHIẾU_CẬP_NHẬT'!J5:J1000,E5)
A6: Dự án được chọn thí điểm | B6: =COUNTIF('DANH_MỤC_DỰ_ÁN'!O5:O200,"Có") | C6: 2 | E6: WATCH | F6: =COUNTIF('PHIẾU_CẬP_NHẬT'!J5:J1000,E6)
A7: Câu hỏi đã đăng ký | B7: =COUNTA('CÂU_HỎI'!A5:A500) | C7: 10–16 | E7: CLARIFY | F7: =COUNTIF('PHIẾU_CẬP_NHẬT'!J5:J1000,E7)
A8: Câu hỏi quá hạn | B8: =COUNTIFS('CÂU_HỎI'!P5:P500,"<"&TODAY(),'CÂU_HỎI'!P5:P500,"<>"&"",'CÂU_HỎI'!Q5:Q500,"<>Đã đóng") | C8: 0 P0/P1; giảm dần tổng | E8: UPDATE SUMMARY | F8: =COUNTIF('PHIẾU_CẬP_NHẬT'!J5:J1000,E8)
A9: Tín hiệu trong inbox | B9: =COUNTA(INBOX!A5:A1000) | C9: Theo thực tế | E9: PROPOSE PRACTICE UPDATE | F9: =COUNTIF('PHIẾU_CẬP_NHẬT'!J5:J1000,E9)
A10: P0/P1 chưa hoàn tất | B10: =COUNTIFS(INBOX!L5:L1000,"P0",INBOX!M5:M1000,"<>Hoàn tất",INBOX!A5:A1000,"<>")+COUNTIFS(INBOX!L5:L1000,"P1",INBOX!M5:M1000,"<>Hoàn tất",INBOX!A5:A1000,"<>") | C10: 0 quá hạn | E10: SAFETY ESCALATION | F10: =COUNTIF('PHIẾU_CẬP_NHẬT'!J5:J1000,E10)
A11: Phiếu cập nhật đã tạo | B11: =COUNTA('PHIẾU_CẬP_NHẬT'!A5:A1000) | C11: ≥6 | E11: RETIRE/SUPERSEDE | F11: =COUNTIF('PHIẾU_CẬP_NHẬT'!J5:J1000,E11)
A12: Phiếu đã duyệt | B12: =COUNTIF('PHIẾU_CẬP_NHẬT'!S5:S1000,"ĐÃ DUYỆT") | C12: ≥6 vào ngày 90
A13: Tỷ lệ nguồn đã xác minh | B13: =IFERROR(COUNTIF('PHIẾU_CẬP_NHẬT'!T5:T1000,"Đã xác minh")/COUNTA('PHIẾU_CẬP_NHẬT'!A5:A1000),0) | C13: ≥90%
A14: Tỷ lệ kiểm tra an toàn | B14: =IFERROR(COUNTIF('PHIẾU_CẬP_NHẬT'!U5:U1000,"Đã xác minh")/COUNTA('PHIẾU_CẬP_NHẬT'!A5:A1000),0) | C14: 100% P0/P1
A15: Quyết định đã ghi nhật ký | B15: =COUNTA('NHẬT_KÝ_QĐ'!A5:A1000) | C15: 100% phiếu đã duyệt
A16: Nhiệm vụ 90 ngày đã đóng | B16: =COUNTIF('CHECKLIST_90_NGÀY'!F5:F200,"Đã đóng") | C16: 11
A19: GHI NHỚ AN TOÀN
A20: AI chỉ hỗ trợ tìm kiếm, trích xuất, so sánh và soạn nháp. Không tự thay đổi thực hành, không tự gán GRADE, không dùng nguồn chưa xác minh và không xử lý thông tin định danh người bệnh.
A24: ⚠️ Cần bác sĩ kiểm chứng trước khi áp dụng lâm sàng.

Sheet HƯỚNG_DẪN
A1: DASHBOARD DANH MỤC CẬP NHẬT CHỨNG CỨ ĐA CHUYÊN NGÀNH
A2: Bản khởi động 90 ngày — dùng cho quản trị chương trình, không phải công cụ tự quyết định lâm sàng.
A4: BƯỚC | B4: CÁCH DÙNG
A5: Bắt đầu | B5: Chấm điểm các dự án trong sheet DANH_MỤC_DỰ_ÁN và chọn đúng 2 dự án thí điểm.
A6: Câu hỏi | B6: Mỗi dự án thí điểm tạo 5–8 câu hỏi trong CÂU_HỎI; mỗi câu hỏi phải có baseline, chủ sở hữu và ngày rà soát.
A7: Nguồn | B7: Đăng ký nguồn chính thức và chiến lược giám sát trong NGUỒN; ghi phiên bản, PMID/DOI/URL và ngày truy cập.
A8: Tín hiệu | B8: Mọi bài/guideline/cảnh báo mới vào INBOX; khử trùng, kiểm tra phạm vi và phân loại P0–P3.
A9: Phiếu | B9: Tín hiệu cần thẩm định được theo dõi trong PHIẾU_CẬP_NHẬT. Không coi là đã duyệt khi thiếu bác sĩ chuyên ngành.
A10: Quyết định | B10: Mọi quyết định được ghi vào NHẬT_KÝ_QĐ với người duyệt, lý do, nguồn và ngày đánh giá lại.
A11: Dashboard | B11: DASHBOARD tổng hợp tự động. Số liệu trống cho đến khi các sheet vận hành được điền.
A12: An toàn | B12: P0: xử lý trong ngày làm việc. AI không tự thay đổi phác đồ; không lưu thông tin định danh người bệnh.
A14: Quy ước màu
A15: P0/Quá hạn
A16: P1/Cần chú ý
A17: Đang xử lý
A18: Đã hoàn tất
A19: Trường thông tin
A21: ⚠️ Cần bác sĩ kiểm chứng trước khi áp dụng lâm sàng.

Sheet DANH_MỤC_DỰ_ÁN
A1: DANH MỤC DỰ ÁN CHUYÊN NGÀNH
A2: Chấm các cột H–M từ 1 đến 5. Điểm ưu tiên tối đa 100; cột N được tính tự động.
A4: Mã dự án | B4: Chuyên ngành | C4: Nhóm | D4: Nguồn lõi gợi ý | E4: Trưởng chuyên ngành | F4: Phương pháp viên | G4: Trạng thái | H4: Nguy cơ an toàn (25%) | I4: Gánh nặng bệnh (20%) | J4: Tốc độ thay đổi (15%) | K4: Biến thiên thực hành (15%) | L4: Khả năng triển khai (15%) | M4: Khả năng đo tác động (10%) | N4: Điểm ưu tiên /100 | O4: Chọn thí điểm | P4: Ngày bắt đầu | Q4: Ngày rà soát tiếp | R4: Mục tiêu 90 ngày | S4: Ghi chú
A5: PRJ-CARD | B5: Tim mạch | C5: Nội khoa | D5: ESC; ACC/AHA; WHO; Bộ Y tế; PubMed | E5: Người dùng — tự phụ trách | F5: Người dùng — tự phụ trách | G5: Đang thiết lập | N5: =IF(COUNTA(H5:M5)=0,"",ROUND(SUMPRODUCT(H5:M5,{25,20,15,15,15,10})/5,1)) | O5: Có | R5: Thiết lập 5–8 câu hỏi; hoàn thành ≥3 Evidence Update Cards
A6: PRJ-ENDO | B6: Nội tiết – Đái tháo đường | C6: Nội khoa | D6: ADA; EASD; WHO; Bộ Y tế; PubMed | E6: Người dùng — tự phụ trách | F6: Người dùng — tự phụ trách | G6: Đang thiết lập | N6: =IF(COUNTA(H6:M6)=0,"",ROUND(SUMPRODUCT(H6:M6,{25,20,15,15,15,10})/5,1)) | O6: Có | R6: Thiết lập 5–8 câu hỏi; hoàn thành ≥3 Evidence Update Cards
A7: PRJ-NEPH | B7: Thận | C7: Nội khoa | D7: KDIGO; Bộ Y tế; PubMed | F7: Người dùng — tự phụ trách | G7: Đang thiết lập | N7: =IF(COUNTA(H7:M7)=0,"",ROUND(SUMPRODUCT(H7:M7,{25,20,15,15,15,10})/5,1)) | O7: Không | R7: Thiết lập 5–8 câu hỏi; hoàn thành ≥3 Evidence Update Cards
A8: PRJ-RESP | B8: Hô hấp | C8: Nội khoa | D8: GOLD; GINA; WHO; Bộ Y tế; PubMed | F8: Người dùng — tự phụ trách | G8: Đang thiết lập | N8: =IF(COUNTA(H8:M8)=0,"",ROUND(SUMPRODUCT(H8:M8,{25,20,15,15,15,10})/5,1)) | O8: Không | R8: Thiết lập 5–8 câu hỏi; hoàn thành ≥3 Evidence Update Cards
A9: PRJ-GIHEP | B9: Tiêu hóa – Gan mật | C9: Nội khoa | D9: AASLD; EASL; WHO; Bộ Y tế; PubMed | F9: Người dùng — tự phụ trách | G9: Đang thiết lập | N9: =IF(COUNTA(H9:M9)=0,"",ROUND(SUMPRODUCT(H9:M9,{25,20,15,15,15,10})/5,1)) | O9: Không | R9: Thiết lập 5–8 câu hỏi; hoàn thành ≥3 Evidence Update Cards
A10: PRJ-RHEU | B10: Cơ xương khớp | C10: Nội khoa | D10: EULAR; ACR; Bộ Y tế; PubMed | F10: Người dùng — tự phụ trách | G10: Đang thiết lập | N10: =IF(COUNTA(H10:M10)=0,"",ROUND(SUMPRODUCT(H10:M10,{25,20,15,15,15,10})/5,1)) | O10: Không | R10: Thiết lập 5–8 câu hỏi; hoàn thành ≥3 Evidence Update Cards
A11: PRJ-IDAMS | B11: Truyền nhiễm – Quản lý kháng sinh | C11: Nhiễm | D11: WHO; IDSA; WHO AWaRe; Bộ Y tế; PubMed | F11: Người dùng — tự phụ trách | G11: Đang thiết lập | N11: =IF(COUNTA(H11:M11)=0,"",ROUND(SUMPRODUCT(H11:M11,{25,20,15,15,15,10})/5,1)) | O11: Không | R11: Thiết lập 5–8 câu hỏi; hoàn thành ≥3 Evidence Update Cards
A12: PRJ-NEUR | B12: Thần kinh | C12: Thần kinh – tâm thần | D12: AAN; ESO; WHO; Bộ Y tế; PubMed | F12: Người dùng — tự phụ trách | G12: Đang thiết lập | N12: =IF(COUNTA(H12:M12)=0,"",ROUND(SUMPRODUCT(H12:M12,{25,20,15,15,15,10})/5,1)) | O12: Không | R12: Thiết lập 5–8 câu hỏi; hoàn thành ≥3 Evidence Update Cards
A13: PRJ-PSYC | B13: Tâm thần | C13: Thần kinh – tâm thần | D13: WHO; NICE; APA; Bộ Y tế; PubMed | F13: Người dùng — tự phụ trách | G13: Đang thiết lập | N13: =IF(COUNTA(H13:M13)=0,"",ROUND(SUMPRODUCT(H13:M13,{25,20,15,15,15,10})/5,1)) | O13: Không | R13: Thiết lập 5–8 câu hỏi; hoàn thành ≥3 Evidence Update Cards
A14: PRJ-ONCO | B14: Ung bướu – Huyết học | C14: Ung thư | D14: WHO; ESMO; ASCO; Bộ Y tế; PubMed | F14: Người dùng — tự phụ trách | G14: Đang thiết lập | N14: =IF(COUNTA(H14:M14)=0,"",ROUND(SUMPRODUCT(H14:M14,{25,20,15,15,15,10})/5,1)) | O14: Không | R14: Thiết lập 5–8 câu hỏi; hoàn thành ≥3 Evidence Update Cards
A15: PRJ-PEDS | B15: Nhi khoa | C15: Đối tượng đặc biệt | D15: WHO; AAP; Bộ Y tế; PubMed | F15: Người dùng — tự phụ trách | G15: Đang thiết lập | N15: =IF(COUNTA(H15:M15)=0,"",ROUND(SUMPRODUCT(H15:M15,{25,20,15,15,15,10})/5,1)) | O15: Không | R15: Thiết lập 5–8 câu hỏi; hoàn thành ≥3 Evidence Update Cards
A16: PRJ-OBGY | B16: Sản phụ khoa | C16: Đối tượng đặc biệt | D16: WHO; FIGO; ACOG; Bộ Y tế; PubMed | F16: Người dùng — tự phụ trách | G16: Đang thiết lập | N16: =IF(COUNTA(H16:M16)=0,"",ROUND(SUMPRODUCT(H16:M16,{25,20,15,15,15,10})/5,1)) | O16: Không | R16: Thiết lập 5–8 câu hỏi; hoàn thành ≥3 Evidence Update Cards
A17: PRJ-CRIT | B17: Cấp cứu – Hồi sức | C17: Cấp tính | D17: WHO; SCCM; ERC/ILCOR; Bộ Y tế; PubMed | F17: Người dùng — tự phụ trách | G17: Đang thiết lập | N17: =IF(COUNTA(H17:M17)=0,"",ROUND(SUMPRODUCT(H17:M17,{25,20,15,15,15,10})/5,1)) | O17: Không | R17: Thiết lập 5–8 câu hỏi; hoàn thành ≥3 Evidence Update Cards
A18: PRJ-DRUG | B18: An toàn thuốc | C18: Xuyên suốt | D18: Cục Quản lý Dược; WHO; EMA; FDA; MHRA | F18: Người dùng — tự phụ trách | G18: Đang thiết lập | N18: =IF(COUNTA(H18:M18)=0,"",ROUND(SUMPRODUCT(H18:M18,{25,20,15,15,15,10})/5,1)) | O18: Không | R18: Thiết lập 5–8 câu hỏi; hoàn thành ≥3 Evidence Update Cards
A19: PRJ-SCORE | B19: Thang điểm và công cụ lâm sàng | C19: Xuyên suốt | D19: Bài gốc; nghiên cứu hiệu chỉnh; guideline nguồn | F19: Người dùng — tự phụ trách | G19: Đang thiết lập | N19: =IF(COUNTA(H19:M19)=0,"",ROUND(SUMPRODUCT(H19:M19,{25,20,15,15,15,10})/5,1)) | O19: Không | R19: Thiết lập 5–8 câu hỏi; hoàn thành ≥3 Evidence Update Cards

Sheet CÂU_HỎI
A1: DANH MỤC CÂU HỎI LÂM SÀNG
A2: Mỗi dự án thí điểm bắt đầu với 5–8 câu hỏi. Không để trống baseline, chủ sở hữu hoặc ngày rà soát tiếp theo.
A4: Mã câu hỏi | B4: Mã dự án | C4: Chủ đề | D4: Population | E4: Intervention/Index/Exposure | F4: Comparator | G4: Outcomes | H4: Time/Setting | I4: Baseline hiện tại | J4: Phiên bản/ngày | K4: PMID/DOI/URL | L4: Chủ sở hữu lâm sàng | M4: Phụ trách phương pháp | N4: Nhịp giám sát | O4: Lần rà soát gần nhất | P4: Rà soát tiếp theo | Q4: Trạng thái | R4: Ưu tiên | S4: Ghi chú
A5: Q-CARD-01 | B5: PRJ-CARD | C5: Tăng huyết áp và đo huyết áp tại nhà | D5: Người lớn ngoại trú có huyết áp tăng hoặc nghi tăng huyết áp; chưa có tình huống cấp cứu tăng huyết áp. | E5: Đo huyết áp chuẩn hóa tại phòng khám kết hợp HBPM/ABPM khi phù hợp; đánh giá nguy cơ tim mạch và quản lý lối sống/thuốc theo guideline — DRAFT. | F5: Đo không chuẩn hóa, chỉ dựa một trị số phòng khám hoặc chăm sóc hiện hành chưa có xác nhận ngoài phòng khám. | G5: Xác nhận chẩn đoán; kiểm soát huyết áp; biến cố tim mạch; tổn thương cơ quan; hạ huyết áp/tác dụng bất lợi. | H5: Ngoại trú; đánh giá ban đầu và tái đánh giá định kỳ hoặc theo sự kiện. | I5: DRAFT — CHƯA DUYỆT: dùng 2024 ESC Guidelines (có corrigendum 11/02/2025) làm baseline cho đo chuẩn hóa, xác nhận ngoài phòng khám và quản lý dựa trên nguy cơ; cần đối chiếu hướng dẫn Bộ Y tế và nguồn lực HBPM/ABPM tại Việt Nam. | J5: 2024 ESC Elevated Blood Pressure and Hypertension; corrigendum 11/02/2025; truy cập 31/08/2026 | K5: https://www.escardio.org/guidelines/clinical-practice-guidelines/all-esc-practice-guidelines/elevated-blood-pressure-and-hypertension/ | PMID:39210715 | DOI:10.1093/eurheartj/ehae178 | L5: Người dùng — tự phụ trách | M5: Người dùng — tự phụ trách | N5: Theo sự kiện | O5: 46265 | P5: 46370 | Q5: Đang thiết lập | R5: P2 | S5: BACKLOG 1/6 · DRAFT — CHƯA DUYỆT · Nguồn ở cột K chỉ là nguồn khởi đầu, chưa thẩm định cấp câu hỏi · VÒNG LẶP ĐA CHUYÊN NGÀNH 2026-08-26: rà an toàn hằng tuần + chuyên sâu tuần tự theo ngày cột P · BASELINE DRAFT HOÀN THÀNH 31/08/2026 — chờ duyệt lâm sàng/phương pháp
A6: Q-CARD-02 | B6: PRJ-CARD | C6: Rối loạn lipid máu và nguy cơ tim mạch tổng thể | D6: Người lớn ngoại trú cần đánh giá nguy cơ tim mạch và quản lý rối loạn lipid máu. | E6: Phân tầng nguy cơ tổng thể bằng công cụ phù hợp, đánh giá yếu tố điều biến nguy cơ và điều trị hạ lipid theo nguy cơ/mức LDL-C — DRAFT. | F6: Cách đánh giá cũ không cập nhật SCORE2/SCORE2-OP hoặc điều trị không gắn với nguy cơ tổng thể. | G6: LDL-C; biến cố tim mạch lớn; tử vong tim mạch; dung nạp và tác dụng bất lợi của điều trị. | H6: Ngoại trú; đánh giá ban đầu, sau thay đổi điều trị và định kỳ. | I6: DRAFT — CHƯA DUYỆT: 2025 ESC/EAS Focused Update cập nhật phân tầng nguy cơ và các yếu tố điều biến/nghiệm pháp hỗ trợ, đồng thời bổ sung chứng cứ về lựa chọn hạ lipid; không tự chuyển thành mục tiêu điều trị tại cơ sở khi chưa duyệt bối cảnh Việt Nam. | J6: 2025 Focused Update of 2019 ESC/EAS Dyslipidaemias Guidelines; truy cập 31/08/2026 | K6: https://www.escardio.org/news/news-room/congress-news/2025-focused-update-dyslipidaemias/ | PMID:40878289 | DOI:10.1093/eurheartj/ehaf190 | L6: Người dùng — tự phụ trách | M6: Người dùng — tự phụ trách | N6: Theo sự kiện | O6: 46265 | P6: 46370 | Q6: Đang thiết lập | R6: P2 | S6: BACKLOG 2/6 · DRAFT — CHƯA DUYỆT · Nguồn ở cột K chỉ là nguồn khởi đầu, chưa thẩm định cấp câu hỏi · VÒNG LẶP ĐA CHUYÊN NGÀNH 2026-08-26: rà an toàn hằng tuần + chuyên sâu tuần tự theo ngày cột P · BASELINE DRAFT HOÀN THÀNH 31/08/2026 — chờ duyệt lâm sàng/phương pháp
A7: Q-CARD-03 | B7: PRJ-CARD | C7: Rung nhĩ, phòng ngừa đột quỵ và an toàn chống đông | D7: Người lớn ngoại trú có rung nhĩ đã xác nhận hoặc nghi ngờ cần xác nhận và tái đánh giá nguy cơ. | E7: Quản lý tích hợp AF-CARE: bệnh đồng mắc/yếu tố nguy cơ, phòng ngừa huyết khối, kiểm soát triệu chứng và tái đánh giá động; kiểm tra an toàn chống đông — DRAFT. | F7: Chăm sóc phân mảnh hoặc quyết định chống đông/kiểm soát nhịp không có tái đánh giá hệ thống. | G7: Đột quỵ/thuyên tắc hệ thống; chảy máu lớn; triệu chứng; nhập viện; chất lượng sống và tử vong. | H7: Ngoại trú; tái đánh giá định kỳ và khi thay đổi bệnh đồng mắc, thuốc hoặc nguy cơ chảy máu. | I7: DRAFT — CHƯA DUYỆT: dùng 2024 ESC AF Guidelines và khung AF-CARE làm baseline cho quản lý tích hợp, phòng ngừa huyết khối và tái đánh giá động; lựa chọn chống đông cụ thể phải qua bác sĩ và bối cảnh người bệnh. | J7: 2024 ESC Guidelines for atrial fibrillation; truy cập 31/08/2026 | K7: https://www.escardio.org/guidelines/clinical-practice-guidelines/all-esc-practice-guidelines/atrial-fibrillation/ | PMID:39210723 | DOI:10.1093/eurheartj/ehae176 | L7: Người dùng — tự phụ trách | M7: Người dùng — tự phụ trách | N7: Theo sự kiện | O7: 46265 | P7: 46370 | Q7: Đang thiết lập | R7: P2 | S7: BACKLOG 3/6 · DRAFT — CHƯA DUYỆT · Nguồn ở cột K chỉ là nguồn khởi đầu, chưa thẩm định cấp câu hỏi · VÒNG LẶP ĐA CHUYÊN NGÀNH 2026-08-26: rà an toàn hằng tuần + chuyên sâu tuần tự theo ngày cột P · BASELINE DRAFT HOÀN THÀNH 31/08/2026 — chờ duyệt lâm sàng/phương pháp
A8: Q-CARD-04 | B8: PRJ-CARD | C8: Đau ngực ổn định và bệnh mạch vành mạn | D8: Người lớn ngoại trú có đau ngực ổn định/nghi hội chứng vành mạn hoặc bệnh vành mạn đã xác định. | E8: Đánh giá từng bước với xác suất lâm sàng có trọng số yếu tố nguy cơ, lựa chọn xét nghiệm phù hợp và quản lý triệu chứng/phòng biến cố — DRAFT. | F8: Mô hình xác suất cũ hoặc xét nghiệm/điều trị không theo xác suất và đặc điểm người bệnh. | G8: Chẩn đoán bệnh mạch vành tắc nghẽn hoặc ANOCA/INOCA; triệu chứng; biến cố tim mạch; xét nghiệm và thủ thuật không cần thiết. | H8: Ngoại trú; đánh giá ban đầu và theo dõi dài hạn bệnh vành mạn. | I8: DRAFT — CHƯA DUYỆT: 2024 ESC CCS Guidelines cập nhật cách ước tính khả năng bệnh mạch vành và lộ trình chẩn đoán, đồng thời mở rộng ANOCA/INOCA và quản lý dài hạn; dấu hiệu nghi hội chứng vành cấp phải chuyển cấp, không đi theo baseline ngoại trú này. | J8: 2024 ESC Chronic Coronary Syndromes Guidelines; truy cập 31/08/2026 | K8: https://www.escardio.org/guidelines/clinical-practice-guidelines/all-esc-practice-guidelines/chronic-coronary-syndromes/ | PMID:39210710 | DOI:10.1093/eurheartj/ehae177 | L8: Người dùng — tự phụ trách | M8: Người dùng — tự phụ trách | N8: Theo sự kiện | O8: 46265 | P8: 46370 | Q8: Đang thiết lập | R8: P3 | S8: BACKLOG 4/6 · DRAFT — CHƯA DUYỆT · Nguồn ở cột K chỉ là nguồn khởi đầu, chưa thẩm định cấp câu hỏi · VÒNG LẶP ĐA CHUYÊN NGÀNH 2026-08-26: rà an toàn hằng tuần + chuyên sâu tuần tự theo ngày cột P · BASELINE DRAFT HOÀN THÀNH 31/08/2026 — chờ duyệt lâm sàng/phương pháp
A9: Q-CARD-05 | B9: PRJ-CARD | C9: Suy tim ngoại trú, khó thở và phù | D9: Người lớn ngoại trú có suy tim đã xác định hoặc triệu chứng khó thở/phù cần đánh giá nguyên nhân và mức độ ổn định. | E9: Đánh giá có cấu trúc, xác định kiểu hình/phân suất tống máu, tối ưu điều trị theo guideline, theo dõi sung huyết, chức năng thận/điện giải và dấu hiệu mất bù — DRAFT. | F9: Theo dõi triệu chứng đơn thuần hoặc điều trị không được rà soát hệ thống. | G9: Tử vong; nhập viện suy tim; triệu chứng/chức năng; sung huyết; chức năng thận, điện giải và tác dụng bất lợi. | H9: Ngoại trú ổn định hoặc sau xuất viện; chuyển cấp khi có dấu hiệu mất bù/nguy cơ cao. | I9: DRAFT — CHƯA DUYỆT: ESC 2026 là guideline Suy tim mới nhất, thay đổi phân loại theo LVEF, bổ sung tiếp cận theo giai đoạn và cập nhật chỉ định điều trị. Nguồn 2021 + focused update 2023 được giữ làm lịch sử/nền; chưa thay đổi thuốc hoặc pathway cho đến khi hoàn tất thẩm định kết cục, an toàn và khả năng áp dụng tại Việt Nam. | J9: 2026 ESC Guidelines for the management of heart failure; phát hành 28/08/2026; truy cập 01/09/2026 | K9: https://www.escardio.org/guidelines/clinical-practice-guidelines/all-esc-practice-guidelines/heart-failure/ | DOI:10.1093/eurheartj/ehag100 | PMID:chưa thấy chỉ mục 01/09/2026 | L9: Người dùng — tự phụ trách | M9: Người dùng — tự phụ trách | N9: Theo sự kiện | O9: 46266 | P9: 46370 | Q9: Đang thiết lập | R9: P3 | S9: BACKLOG 5/6 · DRAFT — CHƯA DUYỆT · Nguồn ở cột K chỉ là nguồn khởi đầu, chưa thẩm định cấp câu hỏi · VÒNG LẶP ĐA CHUYÊN NGÀNH 2026-08-26: rà an toàn hằng tuần + chuyên sâu tuần tự theo ngày cột P · BASELINE DRAFT HOÀN THÀNH 31/08/2026 — chờ duyệt lâm sàng/phương pháp · TÍN HIỆU 01/09/2026: ESC HF 2026 — P2, chờ thẩm định
A10: Q-CARD-06 | B10: PRJ-CARD | C10: Hồi hộp, ngất và dấu hiệu cần chuyển cấp | D10: Người lớn ngoại trú có hồi hộp, tiền ngất hoặc ngất; loại trừ ngay tình trạng không ổn định. | E10: Bệnh sử/khám/ECG ban đầu có cấu trúc, phân tầng nguy cơ và chọn theo dõi nhịp, xét nghiệm hoặc chuyển cấp theo đặc điểm — DRAFT. | F10: Đánh giá không có cấu trúc hoặc xét nghiệm đại trà không theo nguy cơ. | G10: Phát hiện nguyên nhân tim mạch/nguy cơ cao; tái phát; chấn thương; biến cố nghiêm trọng; nhập viện hoặc xét nghiệm không cần thiết. | H10: Ngoại trú khi ổn định; chuyển cấp ngay nếu có dấu hiệu nguy cơ cao hoặc không ổn định. | I10: DRAFT — CHƯA DUYỆT: 2018 ESC Syncope Guidelines vẫn là guideline ESC hiện hành cho đánh giá ban đầu, phân tầng nguy cơ và lựa chọn xét nghiệm/theo dõi; phần hồi hộp cần liên kết guideline loạn nhịp theo biểu hiện và không trì hoãn chuyển cấp khi có cờ đỏ. | J10: 2018 ESC Guidelines for syncope; kiểm tra lịch xuất bản ESC ngày 31/08/2026 | K10: https://www.escardio.org/guidelines/clinical-practice-guidelines/pocket-guidelines/diagnosis-and-management-of-syncope/ | PMID:29562304 | DOI:10.1093/eurheartj/ehy037 | L10: Người dùng — tự phụ trách | M10: Người dùng — tự phụ trách | N10: Theo sự kiện | O10: 46265 | P10: 46370 | Q10: Đang thiết lập | R10: P3 | S10: BACKLOG 6/6 · DRAFT — CHƯA DUYỆT · Nguồn ở cột K chỉ là nguồn khởi đầu, chưa thẩm định cấp câu hỏi · VÒNG LẶP ĐA CHUYÊN NGÀNH 2026-08-26: rà an toàn hằng tuần + chuyên sâu tuần tự theo ngày cột P · BASELINE DRAFT HOÀN THÀNH 31/08/2026 — chờ duyệt lâm sàng/phương pháp
A11: Q-ENDO-01 | B11: PRJ-ENDO | C11: Sàng lọc và chẩn đoán tiền đái tháo đường, đái tháo đường type 2 | D11: Người lớn ngoại trú chưa chẩn đoán đái tháo đường; phân tầng theo triệu chứng, thai kỳ, thiếu máu/bệnh hemoglobin và nguy cơ cao. | E11: Sàng lọc/chẩn đoán bằng FPG, HbA1c hoặc 2-h PG sau OGTT; can thiệp lối sống và cân nhắc metformin ở nhóm tiền đái tháo đường phù hợp. | F11: Không sàng lọc hoặc chiến lược xét nghiệm khác; chăm sóc chuẩn/giả dược trong dự phòng. | G11: Chẩn đoán đúng, tiến triển thành đái tháo đường, biến cố bất lợi và gánh nặng xét nghiệm; ưu tiên kết cục tuyệt đối khi có. | H11: Ngoại trú; chẩn đoán cần xác nhận nếu không có tăng đường huyết rõ; dự phòng theo dõi ít nhất 3 năm. | I11: DRAFT — CHƯA DUYỆT: Có thể dùng FPG, HbA1c hoặc OGTT theo tiêu chuẩn ADA 2026; HbA1c 5,7–6,4%, FPG 100–125 mg/dL hoặc 2-h PG 140–199 mg/dL xác định tiền đái tháo đường. Nếu không có triệu chứng/tình trạng tăng đường huyết rõ, cần hai kết quả bất thường để xác nhận đái tháo đường. CGM chưa đủ để chẩn đoán. Trong DPP, lối sống giảm nguy cơ tương đối 58% và metformin 31% so với giả dược; NNT 3 năm lần lượt khoảng 6,9 và 13,9 ở quần thể nguy cơ cao của nghiên cứu. | J11: ADA Standards of Care 2026, Sections 2–3; DPP, NEJM 2002 | K11: PMID 41358893; PMID 41358891; PMID 11832527; DOI 10.1056/NEJMoa012512 | L11: Người dùng — tự phụ trách | M11: Người dùng — tự phụ trách | N11: Theo sự kiện | O11: 46272 | P11: 46377 | Q11: Đang thiết lập | R11: P2 | S11: BACKLOG 1/6 · DRAFT — CHƯA DUYỆT · Nguồn ở cột K chỉ là nguồn khởi đầu, chưa thẩm định cấp câu hỏi · VÒNG LẶP ĐA CHUYÊN NGÀNH 2026-08-26: rà an toàn hằng tuần + chuyên sâu tuần tự theo ngày cột P | Baseline Nội tiết 2026-09-07: Kết quả DPP không tự động áp dụng cho mọi người có tiền đái tháo đường; cần đối chiếu nguy cơ, khả năng tham gia lối sống và chống chỉ định. [CẦN BÁC SĨ PHÁN ĐỊNH]
A12: Q-ENDO-02 | B12: PRJ-ENDO | C12: Kiểm soát đường huyết cá thể hóa | D12: Người lớn ngoại trú đái tháo đường type 2, gồm người cao tuổi, đa bệnh, nguy cơ hạ đường huyết hoặc bệnh tim mạch cao. | E12: Đặt mục tiêu HbA1c/các chỉ số CGM cá thể hóa và chọn thuốc dựa trên hiệu quả, hạ đường huyết, cân nặng, tim-thận, chi phí và ưu tiên người bệnh. | F12: Mục tiêu đường huyết ít nghiêm ngặt hơn hoặc phác đồ khác. | G12: Tử vong, MACE, biến chứng vi mạch, hạ đường huyết nặng, tăng cân, gánh nặng điều trị và chất lượng sống. | H12: Ngoại trú; đánh giá lại theo thay đổi bệnh, thuốc và nguy cơ; ACCORD theo dõi trung vị 3,5 năm. | I12: DRAFT — CHƯA DUYỆT: HbA1c <7% phù hợp cho nhiều người lớn không mang thai nếu đạt được an toàn; mục tiêu phải nới lỏng hoặc giảm cường độ khi nguy cơ hạ đường huyết, suy yếu, suy giảm nhận thức/chức năng hay gánh nặng điều trị cao. Không dùng mục tiêu gần bình thường một cách cứng nhắc: ACCORD không giảm có ý nghĩa kết cục tim mạch chính (HR 0,90; KTC 95% 0,78–1,04) nhưng tăng tử vong (HR 1,22; KTC 95% 1,01–1,46) và tăng hạ đường huyết/tăng cân ở nhóm T2D nguy cơ tim mạch cao. | J12: ADA Standards of Care 2026, Sections 6 & 9; ACCORD, NEJM 2008 | K12: PMID 41358894; PMID 41358900; PMID 18539917; DOI 10.1056/NEJMoa0802743 | L12: Người dùng — tự phụ trách | M12: Người dùng — tự phụ trách | N12: Theo sự kiện | O12: 46272 | P12: 46377 | Q12: Đang thiết lập | R12: P2 | S12: BACKLOG 2/6 · DRAFT — CHƯA DUYỆT · Nguồn ở cột K chỉ là nguồn khởi đầu, chưa thẩm định cấp câu hỏi · VÒNG LẶP ĐA CHUYÊN NGÀNH 2026-08-26: rà an toàn hằng tuần + chuyên sâu tuần tự theo ngày cột P | Baseline Nội tiết 2026-09-07: Không suy rộng ACCORD sang người mới mắc/nguy cơ thấp; lựa chọn thuốc và mục tiêu là quyết định lâm sàng cá thể hóa. [CẦN BÁC SĨ PHÁN ĐỊNH]
A13: Q-ENDO-03 | B13: PRJ-ENDO | C13: Thừa cân, béo phì và hội chứng chuyển hóa | D13: Người lớn ngoại trú thừa cân/béo phì, có hoặc không đái tháo đường; lưu ý ngưỡng BMI/vòng eo theo dân số châu Á. | E13: Đánh giá BMI, vòng eo và biến chứng; can thiệp lối sống, dược trị hoặc chuyển đánh giá phẫu thuật theo bối cảnh. | F13: Chăm sóc thông thường, giả dược hoặc chiến lược quản lý cân nặng khác. | G13: Giảm cân duy trì, kiểm soát đường huyết, MACE, biến cố bất lợi, ngừng thuốc, chất lượng sống và khả năng tiếp cận. | H13: Ngoại trú; đánh giá ít nhất hằng năm và sau mỗi thay đổi điều trị; SELECT theo dõi trung bình 39,8 tháng. | I13: DRAFT — CHƯA DUYỆT: Quản lý béo phì cần ngôn ngữ không kỳ thị, mục tiêu cá thể hóa và đánh giá biến chứng; giảm 5–7% cân nặng thường cải thiện đường huyết/yếu tố nguy cơ trung gian. Trong SELECT, semaglutide 2,4 mg/tuần giảm MACE 6,5% so với 8,0% (HR 0,80; KTC 95% 0,72–0,90; ARR 1,5 điểm %, NNT xấp xỉ 67 trong khoảng 40 tháng), nhưng tăng ngừng điều trị do biến cố bất lợi 16,6% so với 8,2%. Quần thể SELECT có bệnh tim mạch sẵn, BMI ≥27 và không đái tháo đường. | J13: ADA Standards of Care 2026, Section 8; SELECT, NEJM 2023; Obesity Standards 2026 | K13: PMID 41358882; PMID 37952131; PMID 42242835; DOI 10.1056/NEJMoa2307563; DOI 10.2337/doci26-0003 | L13: Người dùng — tự phụ trách | M13: Người dùng — tự phụ trách | N13: Theo sự kiện | O13: 46272 | P13: 46377 | Q13: Đang thiết lập | R13: P2 | S13: BACKLOG 3/6 · DRAFT — CHƯA DUYỆT · Nguồn ở cột K chỉ là nguồn khởi đầu, chưa thẩm định cấp câu hỏi · VÒNG LẶP ĐA CHUYÊN NGÀNH 2026-08-26: rà an toàn hằng tuần + chuyên sâu tuần tự theo ngày cột P | Baseline Nội tiết 2026-09-07: Không suy rộng SELECT cho đái tháo đường hoặc dự phòng tiên phát. Nguồn Obesity Standards 2026 là tín hiệu mới, cần duyệt ngưỡng châu Á/Việt Nam và quy trình triển khai. [CẦN BÁC SĨ PHÁN ĐỊNH]
A14: Q-ENDO-04 | B14: PRJ-ENDO | C14: Suy giáp, cường giáp và nhân giáp | D14: Người lớn ngoại trú có triệu chứng/rối loạn xét nghiệm tuyến giáp hoặc nhân giáp; loại trừ thai kỳ và cấp cứu tuyến giáp khỏi baseline chung. | E14: Chiến lược xét nghiệm TSH/FT4 có mục tiêu; điều trị suy/cường giáp; phân tầng siêu âm và chọc hút nhân giáp theo nguy cơ. | F14: Theo dõi, ngưỡng can thiệp khác hoặc giả dược ở suy giáp dưới lâm sàng. | G14: Triệu chứng, chất lượng sống, biến cố tim mạch/xương, phát hiện ung thư có ý nghĩa, thủ thuật không cần thiết và tác hại điều trị. | H14: Ngoại trú; nhịp xét nghiệm/theo dõi tùy chẩn đoán và nguy cơ; không áp dụng cho cơn bão giáp/phù niêm cấp. | I14: DRAFT — CHƯA DUYỆT: Dùng NICE NG145 (cập nhật 12/10/2023, rà lại 03/10/2025) cho khung đánh giá/điều trị tuyến giáp và ETA 2023 cho nhân giáp theo nguy cơ. Ở người ≥65 tuổi có suy giáp dưới lâm sàng nhẹ, TRUST không cho thấy levothyroxine cải thiện điểm triệu chứng (khác biệt 0,0; KTC 95% −2,0 đến 2,1) hoặc mệt mỏi (0,4; −2,1 đến 2,9) sau 1 năm. Hướng dẫn ATA cường giáp 2016 phải được đọc cùng các corrigendum 2017 và 2025. | J14: NICE NG145 updated 2023/reviewed 2025; ETA 2023; ATA 2016 + corrigenda; TRUST 2017 | K14: https://www.nice.org.uk/guidance/ng145/; PMID 37358008; PMID 27521067; PMID 29035639; PMID 40765504; PMID 28402245 | L14: Người dùng — tự phụ trách | M14: Người dùng — tự phụ trách | N14: Theo sự kiện | O14: 46272 | P14: 46377 | Q14: Đang thiết lập | R14: P3 | S14: BACKLOG 4/6 · DRAFT — CHƯA DUYỆT · Nguồn ở cột K chỉ là nguồn khởi đầu, chưa thẩm định cấp câu hỏi · VÒNG LẶP ĐA CHUYÊN NGÀNH 2026-08-26: rà an toàn hằng tuần + chuyên sâu tuần tự theo ngày cột P | Baseline Nội tiết 2026-09-07: TRUST chỉ áp dụng cho người lớn tuổi với suy giáp dưới lâm sàng nhẹ; không áp dụng cho suy giáp rõ, thai kỳ hoặc TSH rất cao. [CẦN BÁC SĨ PHÁN ĐỊNH]
A15: Q-ENDO-05 | B15: PRJ-ENDO | C15: Tầm soát biến chứng mắt, thận, thần kinh và bàn chân | D15: Người ngoại trú đái tháo đường type 1 từ 5 năm trở lên và mọi người đái tháo đường type 2; phân tầng theo nguy cơ thận, mắt, thần kinh và bàn chân. | E15: Sàng lọc định kỳ UACR/eGFR, võng mạc, bệnh thần kinh và khám bàn chân toàn diện; chuyển tuyến theo bất thường. | F15: Không sàng lọc hoặc nhịp sàng lọc khác. | G15: Bệnh thận tiến triển, mất thị lực, loét/cắt cụt chi, chuyển tuyến kịp thời, xét nghiệm/thủ thuật không cần thiết và gánh nặng theo dõi. | H15: Ngoại trú: UACR/eGFR hằng năm ở T1 ≥5 năm và mọi T2; mắt T1 sau 5 năm, T2 lúc chẩn đoán; bàn chân ít nhất hằng năm, mỗi lần khám nếu nguy cơ cao. | I15: DRAFT — CHƯA DUYỆT: ADA 2026 đề nghị UACR ngẫu nhiên và eGFR ít nhất hằng năm ở T1 thời gian bệnh ≥5 năm và mọi T2; khám mắt giãn đồng tử ban đầu sau 5 năm ở T1 và tại chẩn đoán ở T2; đánh giá bàn chân toàn diện ít nhất hằng năm, và kiểm tra mỗi lần khám nếu mất cảm giác bảo vệ hoặc tiền sử loét/cắt cụt. Chưa trích xuất được ARR/NNT cho toàn bộ gói sàng lọc; đây là mốc vận hành từ guideline, không phải ước lượng hiệu quả của một thử nghiệm đơn lẻ. | J15: ADA Standards of Care 2026, Sections 11–12 | K15: PMID 41358881; PMID 41358886; DOI 10.2337/dc26-S011; DOI 10.2337/dc26-S012 | L15: Người dùng — tự phụ trách | M15: Người dùng — tự phụ trách | N15: Theo sự kiện | O15: 46272 | P15: 46377 | Q15: Đang thiết lập | R15: P3 | S15: BACKLOG 5/6 · DRAFT — CHƯA DUYỆT · Nguồn ở cột K chỉ là nguồn khởi đầu, chưa thẩm định cấp câu hỏi · VÒNG LẶP ĐA CHUYÊN NGÀNH 2026-08-26: rà an toàn hằng tuần + chuyên sâu tuần tự theo ngày cột P | Baseline Nội tiết 2026-09-07: Cần địa phương hóa năng lực chụp đáy mắt, UACR và chuyển tuyến; không biến lịch guideline thành bảo đảm lợi ích tuyệt đối. [CẦN BÁC SĨ PHÁN ĐỊNH]
A16: Q-ENDO-06 | B16: PRJ-ENDO | C16: Hạ đường huyết và quản lý ngày ốm | D16: Người lớn ngoại trú đái tháo đường dùng thuốc hạ đường huyết, đặc biệt insulin hoặc nguy cơ hạ đường huyết/nhiễm ceton. | E16: Kế hoạch ngày ốm và phòng-xử trí hạ đường huyết: theo dõi glucose/ketone, điều chỉnh thuốc theo tình trạng ăn uống/mất nước, glucose uống, glucagon, giáo dục và ngưỡng liên hệ/chuyển cấp cứu. | F16: Chăm sóc thông thường hoặc theo dõi đường huyết mao mạch ở người lớn tuổi T1. | G16: Thời gian dưới 70 mg/dL, hạ đường huyết nặng, DKA/HHS, nhập viện, biến cố thuốc và khả năng tự xử trí. | H16: Mỗi lần khám cần rà nguy cơ hạ đường huyết; kích hoạt kế hoạch khi bệnh cấp/ăn uống kém; WISDM theo dõi 6 tháng. | I16: DRAFT — CHƯA DUYỆT: Rà hạ đường huyết mỗi lần khám; người tỉnh có glucose <70 mg/dL dùng carbohydrate tác dụng nhanh và kiểm tra lại sau 15 phút; glucagon cho người dùng insulin/nguy cơ cao và giáo dục người thân. Khi bệnh cấp cần tăng theo dõi glucose, đo ketone nếu dễ nhiễm ceton và điều chỉnh thuốc theo mất nước/ăn uống/chức năng thận—không có quy tắc ngừng thuốc đồng loạt. Trong WISDM ở người ≥60 tuổi T1, CGM giảm thời gian <70 mg/dL khoảng 27 phút/ngày (KTC 95% 16–40) và ghi nhận hạ đường huyết nặng 1 so với 10 trong 6 tháng. | J16: ADA Standards of Care 2026, Section 6; WISDM, JAMA 2020 | K16: PMID 41358894; PMID 32543682; DOI 10.1001/jama.2020.6928 | L16: Người dùng — tự phụ trách | M16: Người dùng — tự phụ trách | N16: Theo sự kiện | O16: 46272 | P16: 46377 | Q16: Đang thiết lập | R16: P3 | S16: BACKLOG 6/6 · DRAFT — CHƯA DUYỆT · Nguồn ở cột K chỉ là nguồn khởi đầu, chưa thẩm định cấp câu hỏi · VÒNG LẶP ĐA CHUYÊN NGÀNH 2026-08-26: rà an toàn hằng tuần + chuyên sâu tuần tự theo ngày cột P | Baseline Nội tiết 2026-09-07: Kết quả WISDM chỉ hỗ trợ CGM ở người lớn tuổi T1; kế hoạch ngày ốm và ngưỡng cấp cứu phải được bác sĩ phê duyệt theo thuốc/bệnh kèm. [CẦN BÁC SĨ PHÁN ĐỊNH]
A17: Q-NEPH-01 | B17: PRJ-NEPH | C17: Phát hiện và phân tầng CKD bằng eGFR và uACR | D17: Người lớn khám ngoại trú có nguy cơ hoặc biểu hiện bệnh thận | E17: CHƯA XÁC LẬP — hoàn thiện PICO khi dự án được kích hoạt | F17: CHƯA XÁC LẬP — hoàn thiện PICO khi dự án được kích hoạt | G17: CHƯA XÁC LẬP — hoàn thiện PICO khi dự án được kích hoạt | H17: Khám ngoại trú; thời gian theo dõi CHƯA XÁC LẬP | I17: CHƯA KHẢO SÁT — DRAFT — CHƯA DUYỆT | J17: Danh mục khởi tạo 2026-08-25 | K17: https://kdigo.org/guidelines/ckd-evaluation-and-management/ | L17: CHƯA GÁN — chỉ gán khi dự án được chọn | M17: Người dùng — tự phụ trách | N17: Theo sự kiện | P17: 46279 | Q17: Đang thiết lập | R17: P2 | S17: BACKLOG 1/6 · DRAFT — CHƯA DUYỆT · Nguồn ở cột K chỉ là nguồn khởi đầu, chưa thẩm định cấp câu hỏi · VÒNG LẶP ĐA CHUYÊN NGÀNH 2026-08-26: rà an toàn hằng tuần + chuyên sâu tuần tự theo ngày cột P
A18: Q-NEPH-02 | B18: PRJ-NEPH | C18: Nguy cơ tiến triển CKD và thời điểm chuyển chuyên khoa | D18: Người lớn khám ngoại trú có nguy cơ hoặc biểu hiện bệnh thận | E18: CHƯA XÁC LẬP — hoàn thiện PICO khi dự án được kích hoạt | F18: CHƯA XÁC LẬP — hoàn thiện PICO khi dự án được kích hoạt | G18: CHƯA XÁC LẬP — hoàn thiện PICO khi dự án được kích hoạt | H18: Khám ngoại trú; thời gian theo dõi CHƯA XÁC LẬP | I18: CHƯA KHẢO SÁT — DRAFT — CHƯA DUYỆT | J18: Danh mục khởi tạo 2026-08-25 | K18: https://kdigo.org/guidelines/ckd-evaluation-and-management/ | L18: CHƯA GÁN — chỉ gán khi dự án được chọn | M18: Người dùng — tự phụ trách | N18: Theo sự kiện | P18: 46279 | Q18: Đang thiết lập | R18: P2 | S18: BACKLOG 2/6 · DRAFT — CHƯA DUYỆT · Nguồn ở cột K chỉ là nguồn khởi đầu, chưa thẩm định cấp câu hỏi · VÒNG LẶP ĐA CHUYÊN NGÀNH 2026-08-26: rà an toàn hằng tuần + chuyên sâu tuần tự theo ngày cột P
A19: Q-NEPH-03 | B19: PRJ-NEPH | C19: Tăng huyết áp và bảo vệ thận | D19: Người lớn khám ngoại trú có nguy cơ hoặc biểu hiện bệnh thận | E19: CHƯA XÁC LẬP — hoàn thiện PICO khi dự án được kích hoạt | F19: CHƯA XÁC LẬP — hoàn thiện PICO khi dự án được kích hoạt | G19: CHƯA XÁC LẬP — hoàn thiện PICO khi dự án được kích hoạt | H19: Khám ngoại trú; thời gian theo dõi CHƯA XÁC LẬP | I19: CHƯA KHẢO SÁT — DRAFT — CHƯA DUYỆT | J19: Danh mục khởi tạo 2026-08-25 | K19: https://kdigo.org/guidelines/ckd-evaluation-and-management/ | L19: CHƯA GÁN — chỉ gán khi dự án được chọn | M19: Người dùng — tự phụ trách | N19: Theo sự kiện | P19: 46279 | Q19: Đang thiết lập | R19: P2 | S19: BACKLOG 3/6 · DRAFT — CHƯA DUYỆT · Nguồn ở cột K chỉ là nguồn khởi đầu, chưa thẩm định cấp câu hỏi · VÒNG LẶP ĐA CHUYÊN NGÀNH 2026-08-26: rà an toàn hằng tuần + chuyên sâu tuần tự theo ngày cột P
A20: Q-NEPH-04 | B20: PRJ-NEPH | C20: Protein niệu và tiểu máu | D20: Người lớn khám ngoại trú có nguy cơ hoặc biểu hiện bệnh thận | E20: CHƯA XÁC LẬP — hoàn thiện PICO khi dự án được kích hoạt | F20: CHƯA XÁC LẬP — hoàn thiện PICO khi dự án được kích hoạt | G20: CHƯA XÁC LẬP — hoàn thiện PICO khi dự án được kích hoạt | H20: Khám ngoại trú; thời gian theo dõi CHƯA XÁC LẬP | I20: CHƯA KHẢO SÁT — DRAFT — CHƯA DUYỆT | J20: Danh mục khởi tạo 2026-08-25 | K20: https://kdigo.org/guidelines/ckd-evaluation-and-management/ | L20: CHƯA GÁN — chỉ gán khi dự án được chọn | M20: Người dùng — tự phụ trách | N20: Theo sự kiện | P20: 46279 | Q20: Đang thiết lập | R20: P3 | S20: BACKLOG 4/6 · DRAFT — CHƯA DUYỆT · Nguồn ở cột K chỉ là nguồn khởi đầu, chưa thẩm định cấp câu hỏi · VÒNG LẶP ĐA CHUYÊN NGÀNH 2026-08-26: rà an toàn hằng tuần + chuyên sâu tuần tự theo ngày cột P
A21: Q-NEPH-05 | B21: PRJ-NEPH | C21: AKI liên quan mất nước hoặc thuốc | D21: Người lớn khám ngoại trú có nguy cơ hoặc biểu hiện bệnh thận | E21: CHƯA XÁC LẬP — hoàn thiện PICO khi dự án được kích hoạt | F21: CHƯA XÁC LẬP — hoàn thiện PICO khi dự án được kích hoạt | G21: CHƯA XÁC LẬP — hoàn thiện PICO khi dự án được kích hoạt | H21: Khám ngoại trú; thời gian theo dõi CHƯA XÁC LẬP | I21: CHƯA KHẢO SÁT — DRAFT — CHƯA DUYỆT | J21: Danh mục khởi tạo 2026-08-25 | K21: https://kdigo.org/guidelines/ckd-evaluation-and-management/ | L21: CHƯA GÁN — chỉ gán khi dự án được chọn | M21: Người dùng — tự phụ trách | N21: Theo sự kiện | P21: 46279 | Q21: Đang thiết lập | R21: P3 | S21: BACKLOG 5/6 · DRAFT — CHƯA DUYỆT · Nguồn ở cột K chỉ là nguồn khởi đầu, chưa thẩm định cấp câu hỏi · VÒNG LẶP ĐA CHUYÊN NGÀNH 2026-08-26: rà an toàn hằng tuần + chuyên sâu tuần tự theo ngày cột P
A22: Q-NEPH-06 | B22: PRJ-NEPH | C22: Rối loạn kali, natri và chỉnh liều thuốc theo chức năng thận | D22: Người lớn khám ngoại trú có nguy cơ hoặc biểu hiện bệnh thận | E22: CHƯA XÁC LẬP — hoàn thiện PICO khi dự án được kích hoạt | F22: CHƯA XÁC LẬP — hoàn thiện PICO khi dự án được kích hoạt | G22: CHƯA XÁC LẬP — hoàn thiện PICO khi dự án được kích hoạt | H22: Khám ngoại trú; thời gian theo dõi CHƯA XÁC LẬP | I22: CHƯA KHẢO SÁT — DRAFT — CHƯA DUYỆT | J22: Danh mục khởi tạo 2026-08-25 | K22: https://kdigo.org/guidelines/ckd-evaluation-and-management/ | L22: CHƯA GÁN — chỉ gán khi dự án được chọn | M22: Người dùng — tự phụ trách | N22: Theo sự kiện | P22: 46279 | Q22: Đang thiết lập | R22: P3 | S22: BACKLOG 6/6 · DRAFT — CHƯA DUYỆT · Nguồn ở cột K chỉ là nguồn khởi đầu, chưa thẩm định cấp câu hỏi · VÒNG LẶP ĐA CHUYÊN NGÀNH 2026-08-26: rà an toàn hằng tuần + chuyên sâu tuần tự theo ngày cột P
A23: Q-RESP-01 | B23: PRJ-RESP | C23: Chẩn đoán và kiểm soát hen | D23: Người lớn và trẻ em khám ngoại trú vì triệu chứng hoặc bệnh hô hấp | E23: CHƯA XÁC LẬP — hoàn thiện PICO khi dự án được kích hoạt | F23: CHƯA XÁC LẬP — hoàn thiện PICO khi dự án được kích hoạt | G23: CHƯA XÁC LẬP — hoàn thiện PICO khi dự án được kích hoạt | H23: Khám ngoại trú; thời gian theo dõi CHƯA XÁC LẬP | I23: CHƯA KHẢO SÁT — DRAFT — CHƯA DUYỆT | J23: Danh mục khởi tạo 2026-08-25 | K23: https://ginasthma.org/reports/ ; https://goldcopd.org/2026-gold-report-and-pocket-guide/ | L23: CHƯA GÁN — chỉ gán khi dự án được chọn | M23: Người dùng — tự phụ trách | N23: Theo sự kiện | P23: 46286 | Q23: Đang thiết lập | R23: P2 | S23: BACKLOG 1/6 · DRAFT — CHƯA DUYỆT · Nguồn ở cột K chỉ là nguồn khởi đầu, chưa thẩm định cấp câu hỏi · VÒNG LẶP ĐA CHUYÊN NGÀNH 2026-08-26: rà an toàn hằng tuần + chuyên sâu tuần tự theo ngày cột P
A24: Q-RESP-02 | B24: PRJ-RESP | C24: Phát hiện COPD và chỉ định hô hấp ký | D24: Người lớn và trẻ em khám ngoại trú vì triệu chứng hoặc bệnh hô hấp | E24: CHƯA XÁC LẬP — hoàn thiện PICO khi dự án được kích hoạt | F24: CHƯA XÁC LẬP — hoàn thiện PICO khi dự án được kích hoạt | G24: CHƯA XÁC LẬP — hoàn thiện PICO khi dự án được kích hoạt | H24: Khám ngoại trú; thời gian theo dõi CHƯA XÁC LẬP | I24: CHƯA KHẢO SÁT — DRAFT — CHƯA DUYỆT | J24: Danh mục khởi tạo 2026-08-25 | K24: https://ginasthma.org/reports/ ; https://goldcopd.org/2026-gold-report-and-pocket-guide/ | L24: CHƯA GÁN — chỉ gán khi dự án được chọn | M24: Người dùng — tự phụ trách | N24: Theo sự kiện | P24: 46286 | Q24: Đang thiết lập | R24: P2 | S24: BACKLOG 2/6 · DRAFT — CHƯA DUYỆT · Nguồn ở cột K chỉ là nguồn khởi đầu, chưa thẩm định cấp câu hỏi · VÒNG LẶP ĐA CHUYÊN NGÀNH 2026-08-26: rà an toàn hằng tuần + chuyên sâu tuần tự theo ngày cột P
A25: Q-RESP-03 | B25: PRJ-RESP | C25: Kỹ thuật dụng cụ hít và tuân thủ | D25: Người lớn và trẻ em khám ngoại trú vì triệu chứng hoặc bệnh hô hấp | E25: CHƯA XÁC LẬP — hoàn thiện PICO khi dự án được kích hoạt | F25: CHƯA XÁC LẬP — hoàn thiện PICO khi dự án được kích hoạt | G25: CHƯA XÁC LẬP — hoàn thiện PICO khi dự án được kích hoạt | H25: Khám ngoại trú; thời gian theo dõi CHƯA XÁC LẬP | I25: CHƯA KHẢO SÁT — DRAFT — CHƯA DUYỆT | J25: Danh mục khởi tạo 2026-08-25 | K25: https://ginasthma.org/reports/ ; https://goldcopd.org/2026-gold-report-and-pocket-guide/ | L25: CHƯA GÁN — chỉ gán khi dự án được chọn | M25: Người dùng — tự phụ trách | N25: Theo sự kiện | P25: 46286 | Q25: Đang thiết lập | R25: P2 | S25: BACKLOG 3/6 · DRAFT — CHƯA DUYỆT · Nguồn ở cột K chỉ là nguồn khởi đầu, chưa thẩm định cấp câu hỏi · VÒNG LẶP ĐA CHUYÊN NGÀNH 2026-08-26: rà an toàn hằng tuần + chuyên sâu tuần tự theo ngày cột P
A26: Q-RESP-04 | B26: PRJ-RESP | C26: Ho mạn, khó thở và dấu hiệu báo động | D26: Người lớn và trẻ em khám ngoại trú vì triệu chứng hoặc bệnh hô hấp | E26: CHƯA XÁC LẬP — hoàn thiện PICO khi dự án được kích hoạt | F26: CHƯA XÁC LẬP — hoàn thiện PICO khi dự án được kích hoạt | G26: CHƯA XÁC LẬP — hoàn thiện PICO khi dự án được kích hoạt | H26: Khám ngoại trú; thời gian theo dõi CHƯA XÁC LẬP | I26: CHƯA KHẢO SÁT — DRAFT — CHƯA DUYỆT | J26: Danh mục khởi tạo 2026-08-25 | K26: https://ginasthma.org/reports/ ; https://goldcopd.org/2026-gold-report-and-pocket-guide/ | L26: CHƯA GÁN — chỉ gán khi dự án được chọn | M26: Người dùng — tự phụ trách | N26: Theo sự kiện | P26: 46286 | Q26: Đang thiết lập | R26: P3 | S26: BACKLOG 4/6 · DRAFT — CHƯA DUYỆT · Nguồn ở cột K chỉ là nguồn khởi đầu, chưa thẩm định cấp câu hỏi · VÒNG LẶP ĐA CHUYÊN NGÀNH 2026-08-26: rà an toàn hằng tuần + chuyên sâu tuần tự theo ngày cột P
A27: Q-RESP-05 | B27: PRJ-RESP | C27: Đợt cấp hen hoặc COPD | D27: Người lớn và trẻ em khám ngoại trú vì triệu chứng hoặc bệnh hô hấp | E27: CHƯA XÁC LẬP — hoàn thiện PICO khi dự án được kích hoạt | F27: CHƯA XÁC LẬP — hoàn thiện PICO khi dự án được kích hoạt | G27: CHƯA XÁC LẬP — hoàn thiện PICO khi dự án được kích hoạt | H27: Khám ngoại trú; thời gian theo dõi CHƯA XÁC LẬP | I27: CHƯA KHẢO SÁT — DRAFT — CHƯA DUYỆT | J27: Danh mục khởi tạo 2026-08-25 | K27: https://ginasthma.org/reports/ ; https://goldcopd.org/2026-gold-report-and-pocket-guide/ | L27: CHƯA GÁN — chỉ gán khi dự án được chọn | M27: Người dùng — tự phụ trách | N27: Theo sự kiện | P27: 46286 | Q27: Đang thiết lập | R27: P3 | S27: BACKLOG 5/6 · DRAFT — CHƯA DUYỆT · Nguồn ở cột K chỉ là nguồn khởi đầu, chưa thẩm định cấp câu hỏi · VÒNG LẶP ĐA CHUYÊN NGÀNH 2026-08-26: rà an toàn hằng tuần + chuyên sâu tuần tự theo ngày cột P
A28: Q-RESP-06 | B28: PRJ-RESP | C28: Cai thuốc lá, tiêm chủng và phục hồi chức năng hô hấp | D28: Người lớn và trẻ em khám ngoại trú vì triệu chứng hoặc bệnh hô hấp | E28: CHƯA XÁC LẬP — hoàn thiện PICO khi dự án được kích hoạt | F28: CHƯA XÁC LẬP — hoàn thiện PICO khi dự án được kích hoạt | G28: CHƯA XÁC LẬP — hoàn thiện PICO khi dự án được kích hoạt | H28: Khám ngoại trú; thời gian theo dõi CHƯA XÁC LẬP | I28: CHƯA KHẢO SÁT — DRAFT — CHƯA DUYỆT | J28: Danh mục khởi tạo 2026-08-25 | K28: https://ginasthma.org/reports/ ; https://goldcopd.org/2026-gold-report-and-pocket-guide/ | L28: CHƯA GÁN — chỉ gán khi dự án được chọn | M28: Người dùng — tự phụ trách | N28: Theo sự kiện | P28: 46286 | Q28: Đang thiết lập | R28: P3 | S28: BACKLOG 6/6 · DRAFT — CHƯA DUYỆT · Nguồn ở cột K chỉ là nguồn khởi đầu, chưa thẩm định cấp câu hỏi · VÒNG LẶP ĐA CHUYÊN NGÀNH 2026-08-26: rà an toàn hằng tuần + chuyên sâu tuần tự theo ngày cột P
... A94: Q-SCORE-06 | B94: PRJ-SCORE | C94: Công cụ phân loại cấp cứu, nhiễm trùng và huyết khối | D94: Người bệnh ngoại trú thuộc quần thể mục tiêu của từng công cụ | E94: CHƯA XÁC LẬP — hoàn thiện PICO khi dự án được kích hoạt | F94: CHƯA XÁC LẬP — hoàn thiện PICO khi dự án được kích hoạt | G94: CHƯA XÁC LẬP — hoàn thiện PICO khi dự án được kích hoạt | H94: Khám ngoại trú; thời gian theo dõi CHƯA XÁC LẬP | I94: CHƯA KHẢO SÁT — DRAFT — CHƯA DUYỆT | J94: Danh mục khởi tạo 2026-08-25 | K94: https://www.escardio.org/guidelines/practice-tools/cvd-prevention-toolbox/esc-cvd-risk-calculation-app/ ; https://kdigo.org/guidelines/ckd-evaluation-and-management/ ; https://www.who.int/publications/m/item/primary-care-checklist | L94: CHƯA GÁN — chỉ gán khi dự án được chọn | M94: Người dùng — tự phụ trách | N94: Theo sự kiện | P94: 46363 | Q94: Đang thiết lập | R94: P3 | S94: BACKLOG 6/6 · DRAFT — CHƯA DUYỆT · Nguồn ở cột K chỉ là nguồn khởi đầu, chưa thẩm định cấp câu hỏi · VÒNG LẶP ĐA CHUYÊN NGÀNH 2026-08-26: rà an toàn hằng tuần + chuyên sâu tuần tự theo ngày cột P

Sheet NGUỒN
A1: SOURCE REGISTRY
A2: Đăng ký nguồn chính thức, chiến lược phát hiện và tần suất kiểm tra. Ghi ngày truy cập và phiên bản để có thể audit.
A4: Mã nguồn | B4: Mã dự án | C4: Mã câu hỏi | D4: Tên nguồn | E4: Loại nguồn | F4: Tổ chức/tạp chí | G4: URL chính thức | H4: Phiên bản | I4: Ngày ban hành/cập nhật | J4: Ngày truy cập | K4: DOI | L4: PMID | M4: Kênh alert | N4: Nhịp kiểm tra | O4: Đang dùng | P4: Ghi chú
A5: SRC-CARD-2026-001 | B5: PRJ-CARD | C5: Q-CARD-01 | D5: 2024 ESC Guidelines for the management of elevated blood pressure and hypertension | E5: Guideline | F5: European Society of Cardiology | G5: https://www.escardio.org/guidelines/clinical-practice-guidelines/all-esc-practice-guidelines/elevated-blood-pressure-and-hypertension/ | H5: 2024 ESC Elevated Blood Pressure and Hypertension; corrigendum 11/02/2025; truy cập 31/08/2026 | I5: 45534 | J5: 46265 | K5: 10.1093/eurheartj/ehae178 | L5: 39210715 | M5: ESC guideline alert | N5: Theo sự kiện | O5: Có | P5: DRAFT — CHƯA DUYỆT · metadata DOI/PMID và trang chính thức đã kiểm; cần hiệu chỉnh bối cảnh Việt Nam.
A6: SRC-CARD-2026-002 | B6: PRJ-CARD | C6: Q-CARD-02 | D6: 2025 Focused Update of the 2019 ESC/EAS Guidelines for dyslipidaemias | E6: Guideline | F6: European Society of Cardiology | G6: https://www.escardio.org/news/news-room/congress-news/2025-focused-update-dyslipidaemias/ | H6: 2025 Focused Update of 2019 ESC/EAS Dyslipidaemias Guidelines; truy cập 31/08/2026 | I6: 45898 | J6: 46265 | K6: 10.1093/eurheartj/ehaf190 | L6: 40878289 | M6: ESC guideline alert | N6: Theo sự kiện | O6: Có | P6: DRAFT — CHƯA DUYỆT · metadata DOI/PMID và trang chính thức đã kiểm; cần hiệu chỉnh bối cảnh Việt Nam.
A7: SRC-CARD-2026-003 | B7: PRJ-CARD | C7: Q-CARD-03 | D7: 2024 ESC Guidelines for the management of atrial fibrillation | E7: Guideline | F7: European Society of Cardiology | G7: https://www.escardio.org/guidelines/clinical-practice-guidelines/all-esc-practice-guidelines/atrial-fibrillation/ | H7: 2024 ESC Guidelines for atrial fibrillation; truy cập 31/08/2026 | I7: 45534 | J7: 46265 | K7: 10.1093/eurheartj/ehae176 | L7: 39210723 | M7: ESC guideline alert | N7: Theo sự kiện | O7: Có | P7: DRAFT — CHƯA DUYỆT · metadata DOI/PMID và trang chính thức đã kiểm; cần hiệu chỉnh bối cảnh Việt Nam.
A8: SRC-CARD-2026-004 | B8: PRJ-CARD | C8: Q-CARD-04 | D8: 2024 ESC Guidelines for the management of chronic coronary syndromes | E8: Guideline | F8: European Society of Cardiology | G8: https://www.escardio.org/guidelines/clinical-practice-guidelines/all-esc-practice-guidelines/chronic-coronary-syndromes/ | H8: 2024 ESC Chronic Coronary Syndromes Guidelines; truy cập 31/08/2026 | I8: 45534 | J8: 46265 | K8: 10.1093/eurheartj/ehae177 | L8: 39210710 | M8: ESC guideline alert | N8: Theo sự kiện | O8: Có | P8: DRAFT — CHƯA DUYỆT · metadata DOI/PMID và trang chính thức đã kiểm; cần hiệu chỉnh bối cảnh Việt Nam.
A9: SRC-CARD-2026-005 | B9: PRJ-CARD | C9: Q-CARD-05 | D9: 2023 Focused Update of the 2021 ESC Guidelines for heart failure | E9: Guideline | F9: European Society of Cardiology | G9: https://www.escardio.org/guidelines/clinical-practice-guidelines/all-esc-practice-guidelines/focused-update-on-heart-failure/ | H9: 2021 ESC Heart Failure Guidelines + 2023 Focused Update; truy cập 31/08/2026 | I9: 45163 | J9: 46265 | K9: 10.1093/eurheartj/ehad195 | L9: 37622666 | M9: ESC guideline alert | N9: Theo sự kiện | O9: Có | P9: DRAFT — CHƯA DUYỆT · metadata DOI/PMID và trang chính thức đã kiểm; cần hiệu chỉnh bối cảnh Việt Nam.
A10: SRC-CARD-2026-006 | B10: PRJ-CARD | C10: Q-CARD-06 | D10: 2018 ESC Guidelines for the diagnosis and management of syncope | E10: Guideline | F10: European Society of Cardiology | G10: https://www.escardio.org/guidelines/clinical-practice-guidelines/pocket-guidelines/diagnosis-and-management-of-syncope/ | H10: 2018 ESC Guidelines for syncope; kiểm tra lịch xuất bản ESC ngày 31/08/2026 | I10: 43178 | J10: 46265 | K10: 10.1093/eurheartj/ehy037 | L10: 29562304 | M10: ESC guideline alert | N10: Theo sự kiện | O10: Có | P10: DRAFT — CHƯA DUYỆT · metadata DOI/PMID và trang chính thức đã kiểm; cần hiệu chỉnh bối cảnh Việt Nam.
A11: SRC-CARD-2026-007 | B11: PRJ-CARD | C11: Q-CARD-05 | D11: 2021 ESC Guidelines for the diagnosis and treatment of acute and chronic heart failure | E11: Guideline | F11: European Society of Cardiology | G11: https://www.escardio.org/Guidelines/Clinical-Practice-Guidelines/Acute-and-Chronic-Heart-Failure | H11: 2021 ESC Heart Failure Guidelines; dùng kèm 2023 Focused Update | I11: 44435 | J11: 46265 | K11: 10.1093/eurheartj/ehab368 | L11: 34447992 | M11: ESC guideline alert | N11: Theo sự kiện | O11: Có | P11: DRAFT — CHƯA DUYỆT · nguồn nền; không thay thế focused update 2023.
A12: SRC-CARD-2026-008 | B12: PRJ-CARD | C12: Q-CARD-05 | D12: 2026 ESC Guidelines for the management of heart failure | E12: Guideline | F12: European Society of Cardiology | G12: https://www.escardio.org/guidelines/clinical-practice-guidelines/all-esc-practice-guidelines/heart-failure/ | H12: 2026 ESC Heart Failure; phát hành 28/08/2026; truy cập 01/09/2026 | I12: 46262 | J12: 46266 | K12: 10.1093/eurheartj/ehag100 | L12: Chưa thấy chỉ mục 01/09/2026 | M12: ESC guideline alert | N12: Theo sự kiện | O12: Có | P12: DRAFT — CHƯA DUYỆT · nguồn mới nhất đã xác minh; chưa hoàn tất thẩm định kết cục, an toàn và bối cảnh Việt Nam.
A13: SRC-ENDO-2026-001 | B13: PRJ-ENDO | C13: Q-ENDO-01 | D13: 2. Diagnosis and Classification of Diabetes: Standards of Care in Diabetes—2026 | E13: Guideline | F13: American Diabetes Association | G13: https://diabetesjournals.org/care/article/49/Supplement_1/S27/163926/2-Diagnosis-and-Classification-of-Diabetes | H13: 2026 | I13: 46023 | J13: 46272 | K13: 10.2337/dc26-S002 | L13: 41358893 | M13: Rà thủ công + nguồn chính thức | N13: 15 tuần | O13: Có | P13: DRAFT — CHƯA DUYỆT. Tiêu chuẩn chẩn đoán; xác nhận; giới hạn HbA1c/CGM.
A14: SRC-ENDO-2026-002 | B14: PRJ-ENDO | C14: Q-ENDO-01 | D14: 3. Prevention or Delay of Diabetes and Associated Comorbidities: Standards of Care in Diabetes—2026 | E14: Guideline | F14: American Diabetes Association | G14: https://diabetesjournals.org/care/article/49/Supplement_1/S44/163924/3-Prevention-or-Delay-of-Diabetes-and-Associated | H14: 2026 | I14: 46023 | J14: 46272 | K14: 10.2337/dc26-S003 | L14: 41358891 | M14: Rà thủ công + nguồn chính thức | N14: 15 tuần | O14: Có | P14: DRAFT — CHƯA DUYỆT. Dự phòng đái tháo đường ở nhóm nguy cơ cao.
A15: SRC-ENDO-2026-003 | B15: PRJ-ENDO | C15: Q-ENDO-01 | D15: Reduction in the incidence of type 2 diabetes with lifestyle intervention or metformin | E15: RCT | F15: New England Journal of Medicine | G15: https://pubmed.ncbi.nlm.nih.gov/11832527/ | H15: 2002 | I15: 37294 | J15: 46272 | K15: 10.1056/NEJMoa012512 | L15: 11832527 | M15: Rà thủ công + nguồn chính thức | N15: 15 tuần | O15: Có | P15: DRAFT — CHƯA DUYỆT. DPP; hiệu quả tương đối và NNT 3 năm ở quần thể nghiên cứu.
A16: SRC-ENDO-2026-004 | B16: PRJ-ENDO | C16: Q-ENDO-02; Q-ENDO-06 | D16: 6. Glycemic Goals, Hypoglycemia, and Hyperglycemic Crises: Standards of Care in Diabetes—2026 | E16: Guideline | F16: American Diabetes Association | G16: https://diabetesjournals.org/care/article/49/Supplement_1/S132/163927/6-Glycemic-Goals-Hypoglycemia-and-Hyperglycemic | H16: 2026 | I16: 46023 | J16: 46272 | K16: 10.2337/dc26-S006 | L16: 41358894 | M16: Rà thủ công + nguồn chính thức | N16: 15 tuần | O16: Có | P16: DRAFT — CHƯA DUYỆT. Mục tiêu cá thể hóa; hạ đường huyết; ngày ốm và khủng hoảng tăng đường huyết.
... A20: SRC-ENDO-2026-008 | B20: PRJ-ENDO | C20: Q-ENDO-03 | D20: Semaglutide and Cardiovascular Outcomes in Obesity without Diabetes | E20: RCT | F20: New England Journal of Medicine | G20: https://pubmed.ncbi.nlm.nih.gov/37952131/ | H20: 2023 | I20: 45241 | J20: 46272 | K20: 10.1056/NEJMoa2307563 | L20: 37952131 | M20: Rà thủ công + nguồn chính thức | N20: 15 tuần | O20: Có | P20: DRAFT — CHƯA DUYỆT. SELECT; MACE và ngừng thuốc do biến cố bất lợi; không suy rộng ngoài quần thể.
A21: SRC-ENDO-2026-009 | B21: PRJ-ENDO | C21: Q-ENDO-04 | D21: Thyroid disease: assessment and management (NG145) | E21: Guideline | F21: NICE | G21: https://www.nice.org.uk/guidance/ng145/ | H21: Updated 2023; reviewed 2025 | I21: 45211 | J21: 46272 | M21: Rà thủ công + nguồn chính thức | N21: 15 tuần | O21: Có | P21: DRAFT — CHƯA DUYỆT. Khung đánh giá/điều trị; NICE xác nhận rà soát 03/10/2025.
A22: SRC-ENDO-2026-010 | B22: PRJ-ENDO | C22: Q-ENDO-04 | D22: 2023 European Thyroid Association Clinical Practice Guidelines for thyroid nodule management | E22: Guideline | F22: European Thyroid Association | G22: https://pubmed.ncbi.nlm.nih.gov/37358008/ | H22: 2023 | I22: 45100 | J22: 46272 | K22: 10.1530/ETJ-23-0067 | L22: 37358008 | M22: Rà thủ công + nguồn chính thức | N22: 15 tuần | O22: Có | P22: DRAFT — CHƯA DUYỆT. Phân tầng nguy cơ và theo dõi nhân giáp.
A23: SRC-ENDO-2026-011 | B23: PRJ-ENDO | C23: Q-ENDO-04 | D23: 2016 American Thyroid Association Guidelines for Diagnosis and Management of Hyperthyroidism | E23: Guideline | F23: American Thyroid Association | G23: https://pubmed.ncbi.nlm.nih.gov/27521067/ | H23: 2016 + corrections 2017/2025 | I23: 42644 | J23: 46272 | K23: 10.1089/thy.2016.0229 | L23: 27521067 | M23: Rà thủ công + nguồn chính thức | N23: 15 tuần | O23: Có | P23: DRAFT — CHƯA DUYỆT. Phải đọc cùng corrigendum PMID 29035639 và second correction PMID 40765504.
A24: SRC-ENDO-2026-012 | B24: PRJ-ENDO | C24: Q-ENDO-04 | D24: Thyroid Hormone Therapy for Older Adults with Subclinical Hypothyroidism | E24: RCT | F24: New England Journal of Medicine | G24: https://pubmed.ncbi.nlm.nih.gov/28402245/ | H24: 2017 | I24: 42915 | J24: 46272 | K24: 10.1056/NEJMoa1603825 | L24: 28402245 | M24: Rà thủ công + nguồn chính thức | N24: 15 tuần | O24: Có | P24: DRAFT — CHƯA DUYỆT. TRUST; không cải thiện triệu chứng ở người ≥65 tuổi suy giáp dưới lâm sàng nhẹ.
A25: SRC-ENDO-2026-013 | B25: PRJ-ENDO | C25: Q-ENDO-05 | D25: 11. Chronic Kidney Disease and Risk Management: Standards of Care in Diabetes—2026 | E25: Guideline | F25: American Diabetes Association | G25: https://diabetesjournals.org/care/article/49/Supplement_1/S246/163914/11-Chronic-Kidney-Disease-and-Risk-Management | H25: 2026 | I25: 46023 | J25: 46272 | K25: 10.2337/dc26-S011 | L25: 41358881 | M25: Rà thủ công + nguồn chính thức | N25: 15 tuần | O25: Có | P25: DRAFT — CHƯA DUYỆT. Mốc UACR/eGFR và phân tầng nguy cơ thận.
A26: SRC-ENDO-2026-014 | B26: PRJ-ENDO | C26: Q-ENDO-05 | D26: 12. Retinopathy, Neuropathy, and Foot Care: Standards of Care in Diabetes—2026 | E26: Guideline | F26: American Diabetes Association | G26: https://diabetesjournals.org/care/article/49/Supplement_1/S261/163919/12-Retinopathy-Neuropathy-and-Foot-Care-Standards | H26: 2026 | I26: 46023 | J26: 46272 | K26: 10.2337/dc26-S012 | L26: 41358886 | M26: Rà thủ công + nguồn chính thức | N26: 15 tuần | O26: Có | P26: DRAFT — CHƯA DUYỆT. Mốc sàng lọc mắt, thần kinh và bàn chân.
A27: SRC-ENDO-2026-015 | B27: PRJ-ENDO | C27: Q-ENDO-06 | D27: Effect of Continuous Glucose Monitoring on Hypoglycemia in Older Adults With Type 1 Diabetes | E27: RCT | F27: JAMA | G27: https://pubmed.ncbi.nlm.nih.gov/32543682/ | H27: 2020 | I27: 43998 | J27: 46272 | K27: 10.1001/jama.2020.6928 | L27: 32543682 | M27: Rà thủ công + nguồn chính thức | N27: 15 tuần | O27: Có | P27: DRAFT — CHƯA DUYỆT. WISDM; kết cục thời gian hạ đường huyết và biến cố nặng trong 6 tháng.
A28: SRC-ENDO-2026-016 | B28: PRJ-ENDO | C28: Q-ENDO-03 | D28: Screening, diagnosis and clinical staging of people with overweight or obesity: Standards of care in overweight and obesity—2026 | E28: Guideline mới | F28: American Diabetes Association / The Obesity Association | G28: https://doi.org/10.2337/doci26-0003 | H28: 2026 | I28: 46177 | J28: 46272 | K28: 10.2337/doci26-0003 | L28: 42242835 | M28: Rà thủ công + nguồn chính thức | N28: 15 tuần | O28: Có | P28: DRAFT — CHƯA DUYỆT. TÍN HIỆU MỚI P2: chuẩn riêng về sàng lọc/chẩn đoán/phân giai đoạn; cần địa phương hóa ngưỡng châu Á/Việt Nam.

Sheet INBOX
A1: EVIDENCE INBOX
A2: Mọi tín hiệu mới vào đây trước khi thẩm định. Deadline tự tính theo SLA đề xuất: P0 cùng ngày, P1 +7, P2 +30, P3 +90 ngày.
A4: Mã tín hiệu | B4: Ngày phát hiện | C4: Mã dự án | D4: Mã câu hỏi | E4: Tiêu đề | F4: Loại nguồn | G4: DOI | H4: PMID | I4: URL | J4: Trùng lặp | K4: Phạm vi | L4: Ưu tiên | M4: Trạng thái | N4: Người xử lý | O4: Deadline SLA | P4: Ngày hoàn tất | Q4: Số ngày xử lý | R4: Ghi chú
A5: SIG-CARD-2026-001 | B5: 46265 | C5: PRJ-CARD | D5: Q-CARD-01 | E5: Baseline DRAFT: 2024 ESC Guidelines for the management of elevated blood pressure and hypertension | F5: Guideline | G5: 10.1093/eurheartj/ehae178 | H5: 39210715 | I5: https://www.escardio.org/guidelines/clinical-practice-guidelines/all-esc-practice-guidelines/elevated-blood-pressure-and-hypertension/ | J5: Không | K5: Trong phạm vi | L5: P2 | M5: Chờ duyệt | N5: Người dùng — tự phụ trách | O5: =IF(OR(B5="",L5=""),"",B5+IF(L5="P0",0,IF(L5="P1",7,IF(L5="P2",30,90)))) | Q5: =IF(B5="","",IF(P5<>"",P5-B5,TODAY()-B5)) | R5: BASELINE DRAFT — CHƯA DUYỆT; không phải quyết định thay đổi thực hành.
A6: SIG-CARD-2026-002 | B6: 46265 | C6: PRJ-CARD | D6: Q-CARD-02 | E6: Baseline DRAFT: 2025 Focused Update of the 2019 ESC/EAS Guidelines for dyslipidaemias | F6: Guideline | G6: 10.1093/eurheartj/ehaf190 | H6: 40878289 | I6: https://www.escardio.org/news/news-room/congress-news/2025-focused-update-dyslipidaemias/ | J6: Không | K6: Trong phạm vi | L6: P2 | M6: Chờ duyệt | N6: Người dùng — tự phụ trách | O6: =IF(OR(B6="",L6=""),"",B6+IF(L6="P0",0,IF(L6="P1",7,IF(L6="P2",30,90)))) | Q6: =IF(B6="","",IF(P6<>"",P6-B6,TODAY()-B6)) | R6: BASELINE DRAFT — CHƯA DUYỆT; không phải quyết định thay đổi thực hành.
